[2024-05-14T07:44:13.716+0000] {local_task_job_runner.py:120} INFO - ::group::Pre task execution logs
[2024-05-14T07:44:13.726+0000] {taskinstance.py:2076} INFO - Dependencies all met for dep_context=non-requeueable deps ti=<TaskInstance: data_pipeline_jobs104.data_crawler_list manual__2024-05-14T07:44:12.839023+00:00 [queued]>
[2024-05-14T07:44:13.730+0000] {taskinstance.py:2076} INFO - Dependencies all met for dep_context=requeueable deps ti=<TaskInstance: data_pipeline_jobs104.data_crawler_list manual__2024-05-14T07:44:12.839023+00:00 [queued]>
[2024-05-14T07:44:13.731+0000] {taskinstance.py:2306} INFO - Starting attempt 1 of 1
[2024-05-14T07:44:13.736+0000] {taskinstance.py:2330} INFO - Executing <Task(PythonOperator): data_crawler_list> on 2024-05-14 07:44:12.839023+00:00
[2024-05-14T07:44:13.739+0000] {warnings.py:110} WARNING - /home/***/.local/lib/python3.12/site-packages/***/task/task_runner/standard_task_runner.py:61: DeprecationWarning: This process (pid=529) is multi-threaded, use of fork() may lead to deadlocks in the child.
  pid = os.fork()

[2024-05-14T07:44:13.741+0000] {standard_task_runner.py:63} INFO - Started process 531 to run task
[2024-05-14T07:44:13.740+0000] {standard_task_runner.py:90} INFO - Running: ['***', 'tasks', 'run', 'data_pipeline_jobs104', 'data_crawler_list', 'manual__2024-05-14T07:44:12.839023+00:00', '--job-id', '52', '--raw', '--subdir', 'DAGS_FOLDER/data_pipeline_jobs104.py', '--cfg-path', '/tmp/tmpcod5xp4b']
[2024-05-14T07:44:13.742+0000] {standard_task_runner.py:91} INFO - Job 52: Subtask data_crawler_list
[2024-05-14T07:44:13.766+0000] {task_command.py:426} INFO - Running <TaskInstance: data_pipeline_jobs104.data_crawler_list manual__2024-05-14T07:44:12.839023+00:00 [running]> on host 9bf348f884a5
[2024-05-14T07:44:13.805+0000] {taskinstance.py:2648} INFO - Exporting env vars: AIRFLOW_CTX_DAG_OWNER='***' AIRFLOW_CTX_DAG_ID='data_pipeline_jobs104' AIRFLOW_CTX_TASK_ID='data_crawler_list' AIRFLOW_CTX_EXECUTION_DATE='2024-05-14T07:44:12.839023+00:00' AIRFLOW_CTX_TRY_NUMBER='1' AIRFLOW_CTX_DAG_RUN_ID='manual__2024-05-14T07:44:12.839023+00:00'
[2024-05-14T07:44:13.806+0000] {taskinstance.py:430} INFO - ::endgroup::
[2024-05-14T07:44:13.813+0000] {logging_mixin.py:188} INFO - 設定排除44家公司
[2024-05-14T07:44:13.814+0000] {taskinstance.py:441} INFO - ::group::Post task execution logs
[2024-05-14T07:44:13.814+0000] {taskinstance.py:2905} ERROR - Task failed with exception
Traceback (most recent call last):
  File "/home/airflow/.local/lib/python3.12/site-packages/airflow/models/taskinstance.py", line 465, in _execute_task
    result = _execute_callable(context=context, **execute_callable_kwargs)
             ^^^^^^^^^^^^^^^^^^^^^^^^^^^^^^^^^^^^^^^^^^^^^^^^^^^^^^^^^^^^^
  File "/home/airflow/.local/lib/python3.12/site-packages/airflow/models/taskinstance.py", line 432, in _execute_callable
    return execute_callable(context=context, **execute_callable_kwargs)
           ^^^^^^^^^^^^^^^^^^^^^^^^^^^^^^^^^^^^^^^^^^^^^^^^^^^^^^^^^^^^
  File "/home/airflow/.local/lib/python3.12/site-packages/airflow/models/baseoperator.py", line 400, in wrapper
    return func(self, *args, **kwargs)
           ^^^^^^^^^^^^^^^^^^^^^^^^^^^
  File "/home/airflow/.local/lib/python3.12/site-packages/airflow/operators/python.py", line 235, in execute
    return_value = self.execute_callable()
                   ^^^^^^^^^^^^^^^^^^^^^^^
  File "/home/airflow/.local/lib/python3.12/site-packages/airflow/operators/python.py", line 252, in execute_callable
    return self.python_callable(*self.op_args, **self.op_kwargs)
           ^^^^^^^^^^^^^^^^^^^^^^^^^^^^^^^^^^^^^^^^^^^^^^^^^^^^^
  File "/opt/airflow/dags/data_pipeline_jobs104.py", line 59, in data_crawler_list
    crawler = Crawler104(filter_params, user)
                                        ^^^^
NameError: name 'user' is not defined
[2024-05-14T07:44:13.819+0000] {taskinstance.py:1206} INFO - Marking task as FAILED. dag_id=data_pipeline_jobs104, task_id=data_crawler_list, run_id=manual__2024-05-14T07:44:12.839023+00:00, execution_date=20240514T074412, start_date=20240514T074413, end_date=20240514T074413
[2024-05-14T07:44:13.825+0000] {standard_task_runner.py:110} ERROR - Failed to execute job 52 for task data_crawler_list (name 'user' is not defined; 531)
[2024-05-14T07:44:13.841+0000] {local_task_job_runner.py:240} INFO - Task exited with return code 1
[2024-05-14T07:44:13.851+0000] {taskinstance.py:3498} INFO - 0 downstream tasks scheduled from follow-on schedule check
[2024-05-14T07:44:13.853+0000] {local_task_job_runner.py:222} INFO - ::endgroup::
